Workbook

Sheet Purchases
C2: LC Purchase- Usuance Interest Calculation for the month of Apr'26 | I2: Amount in INR
C3: Party Name | D3: Bank Name | E3: Agreed Usuance ROI % | F3: Total BOE Value | G3: Total Interest Charged by Bank | H3: Total Charges (As per Auditor) | I3: Excess/(Short) (Incl. Penal Charge if any) | J3: Management's Remarks | K3: Auditor's Remarks
C4: TATA STEEL LIMITED | E4: 0.076 | F4: =SUMIF($E$10:$E$13,$C$4,N:N) -> 0 | G4: =SUMIF($E$10:$E$13,$C$4,J11:J13) -> 0 | H4: =SUMIF($E$10:$E$14,$C$4,P10:P13) -> 0 | I4: =G4-H4 -> 0
C5: JINDAL STEEL ODISHA LIMITED | D5: UCO Bank | E5: 0.072 | F5: =SUMIFS(O:O,D:D,D5,E:E,C5) -> 2271779.2 | G5: =SUMIFS(M:M,D:D,D5,E:E,C5) -> 42555.69 | H5: =SUMIFS(S:S,D:D,D5,E:E,C5) -> 42555.296 | I5: =G5-H5 -> 0.39449096
C6: JINDAL STEEL ODISHA LIMITED | D6: ICICI Bank | E6: 0.072 | F6: =SUMIFS(O:O,D:D,D6,E:E,C6) -> 641100.75 | G6: =SUMIFS(M:M,D:D,D6,E:E,C6) -> 12010.04 | H6: =SUMIFS(S:S,D:D,D6,E:E,C6) -> 12009.178 | I6: =G6-H6 -> 0.86229479
C7: Total | F7: =SUM(F4:F5) -> 2271779.2 | G7: =SUM(G4:G5) -> 42555.69 | H7: =SUM(H4:H5) -> 42555.296 | I7: =SUM(I4:I5) -> 0.39449096
F9: As per BOE | P9: As per Auditor's calculation | U9: ROI Calculation | X9: SAP | Y9: Difference
C10: Vendor BOE No. | D10: Bank Name | E10: Vendor Name | F10: BOE Date | G10: Invoice Amount / Material Basic (including GST) | H10: Material Basic (excluding GST) | I10: GST on Material Basic | J10: Interest Amount (Excl. GST) | K10: GST on Interest. | L10: TDS u-s 194A | M10: Total Interest (Inc GST) | N10: TDS u-s 194Q | O10: Total BOE Amount | P10: Interest Amount (Excl. GST) | Q10: GST on Interest. | R10: TDS u-s 194A | S10: Total Interest (Inc GST) | T10: TDS u-s 194Q | U10: Int Rate Charged by Bank | V10: Agreed Rate | W10: Difference | X10: Interest as per SAP | Y10: BOE Vs SAP | Z10: BOE Vs Auditor Calculation | AA10: Auditor Remarks
B11: 2027/01 | C11: 102901 | D11: UCO Bank | E11: JINDAL STEEL ODISHA LIMITED | F11: 18.03.2026 | G11: 1559243 | H11: =G11/1.18 -> 1321392.4 | I11: =H11*0.18 -> 237850.63 | J11: 27682 | K11: 4983 | L11: 2768.19 | M11: =J11+K11-L11 -> 29896.81 | N11: 1321.39 | O11: =SUM(H11:L11,N11) -> 1595997.6 | P11: =G11*U11*90/365 -> 27681.903 | Q11: =P11*0.18 -> 4982.7426 | R11: =P11*0.1 -> 2768.1903 | S11: =P11+Q11-R11 -> 29896.455 | T11: =H11*0.1% -> 1321.3924 | U11: 0.072 | V11: 0.072 | W11: =U11-V11 -> 0 | X11: =SUMIFS(SAP!H:H,SAP!P:P, "BOE",SAP!R:R,Purchases!C11,SAP!V:V,Purchases!B11) -> 27682.2 | Y11: =ROUND(J11-X11,0) -> 0 | Z11: =ROUND(J11-P11,0) -> 0 | AA11: OK
B12: 2027/01 | C12: 103010 | D12: UCO Bank | E12: JINDAL STEEL ODISHA LIMITED | F12: 01.04.2026 | G12: 660219 | H12: =G12/1.18 -> 559507.63 | I12: =H12*0.18 -> 100711.37 | J12: 11721 | K12: 2110 | L12: 1172.12 | M12: =J12+K12-L12 -> 12658.88 | N12: 559.51 | O12: =SUM(H12:L12,N12) -> 675781.63 | P12: =G12*U12*90/365 -> 11721.148 | Q12: =P12*0.18 -> 2109.8067 | R12: =P12*0.1 -> 1172.1148 | S12: =P12+Q12-R12 -> 12658.84 | T12: =H12*0.1% -> 559.50763 | U12: 0.072 | V12: 0.072 | W12: =U12-V12 -> 0 | X12: =SUMIFS(SAP!H:H,SAP!P:P, "BOE",SAP!R:R,Purchases!C12,SAP!V:V,Purchases!B12) -> 11721.19 | Y12: =ROUND(J12-X12,0) -> 0 | Z12: =ROUND(J12-P12,0) -> 0 | AA12: OK
B13: 2027/01 | C13: 103011 | D13: ICICI Bank | E13: JINDAL STEEL ODISHA LIMITED | F13: 01.04.2026 | G13: 626336 | H13: =G13/1.18 -> 530793.22 | I13: =H13*0.18 -> 95542.78 | J13: 11120 | K13: 2002 | L13: 1111.96 | M13: =J13+K13-L13 -> 12010.04 | N13: 530.79 | O13: =SUM(H13:L13,N13) -> 641100.75 | P13: =G13*U13*90/365 -> 11119.609 | Q13: =P13*0.18 -> 2001.5296 | R13: =P13*0.1 -> 1111.9609 | S13: =P13+Q13-R13 -> 12009.178 | T13: =H13*0.1% -> 530.79322 | U13: 0.072 | V13: 0.072 | W13: =U13-V13 -> 0 | X13: =SUMIFS(SAP!H:H,SAP!P:P, "BOE",SAP!R:R,Purchases!C13,SAP!V:V,Purchases!B13) -> 11119.49 | Y13: =ROUND(J13-X13,0) -> 1 | Z13: =ROUND(J13-P13,0) -> 0 | AA13: OK
C14: TOTAL | G14: =SUM(G11:G13) -> 2845798 | H14: =SUM(H11:H13) -> 2411693.2 | I14: =SUM(I11:I13) -> 434104.78 | J14: =SUM(J11:J13) -> 50523 | K14: =SUM(K11:K13) -> 9095 | L14: =SUM(L11:L13) -> 5052.27 | M14: =SUM(M11:M13) -> 54565.73 | N14: =SUM(N11:N13) -> 2411.69 | ... T14: =SUM(T11:T13) -> 2411.6932 | W14: =SUM(W11:W13) -> 0 | X14: =SUM(X11:X13) -> 50522.88 | Y14: =SUM(Y11:Y13) -> 1

Sheet Sales
J1: Amount in INR
E2: Particulars | F2: Bank Name | G2: Bill Discounted | H2: Total Interest Expenses ( As per Bank Advice) | I2: Total Interest Expenses ( As per Auditor) | J2: Excess/(Short)
E3: Export Bill Discounted | F3: HDFC | G3: =SUMIFS(O:O,C:C,"Export",D:D,F3) -> 5.2962473e+08 | H3: =SUMIFS(W:W,C:C,"Export",D:D,F3) -> 4021172.8 | I3: =SUMIFS(AD:AD,C:C,"Export",D:D,F3) -> 4020447.9 | J3: =H3-I3 -> 724.85969
E4: Domestic Bill Discounted | F4: HDFC | G4: =SUMIFS(O:O,C:C,"Domestic",D:D,F4) -> 0 | H4: =SUMIFS(W:W,C:C,"DOMESTIC",D:D,F4) -> 0 | I4: =SUMIFS(AD:AD,C:C,"DOMESTIC",D:D,F4) -> 0 | J4: =H4-I4 -> 0
E5: Export Bill Discounted | F5: Kotak | G5: =SUMIFS(O:O,C:C,"Export",D:D,F5) -> 0 | H5: =SUMIFS(W:W,C:C,"Export",D:D,F5) -> 0 | I5: =SUMIFS(AD:AD,C:C,"Export",D:D,F5) -> 0 | J5: =H5-I5 -> 0
E6: Domestic Bill Discounted | F6: Kotak | G6: =SUMIFS(O:O,C:C,"Domestic",D:D,F6) -> 17921042 | H6: =SUMIFS(W:W,C:C,"DOMESTIC",D:D,F6) -> 246280.77 | I6: =SUMIFS(AD:AD,C:C,"DOMESTIC",D:D,F6) -> 246280.77 | J6: =H6-I6 -> 0.0018
E7: Interest Credited | G7: 0 | H7: =SUMIFS(SAP!H:H,SAP!P:P, "Intt Recd",SAP!V:V, "2027/01") -> -53786.75 | I7: =H7 -> -53786.75 | J7: =H7-I7 -> 0
E8: Penal Interest | G8: 0 | H8: =SUMIFS(SAP!H:H,SAP!P:P, "Penal interest",SAP!V:V, "2027/01") -> 59626.4 | I8: =H8 -> 59626.4 | J8: =H8-I8 -> 0
E9: Total | F9: Total | G9: =SUM(G3:G8) -> 5.4754577e+08 | H9: =SUM(H3:H8) -> 4273293.2 | I9: =SUM(I3:I8) -> 4272568.4 | J9: =SUM(J3:J8) -> 724.86149
O11: As per Bank | Z11: As per Auditor
C12: Sales Type | D12: Bank | E12: Customer Name | F12: Discounting Date | G12: Reference No | H12: Invoice No. | I12: Start Date | J12: End Date | K12: No. of days | L12: Bill Discounted Value (Euro) | M12: Currency | N12: Exchange Rate | O12: Bill Discounted Value (INR) | P12: Discounting Interest | Q12: Bill Comm | R12: Courier Postage | S12: FX Conversion | T12: Handling Charges | U12: GST | V12: Total Chgs as per Bank | W12: Total Chgs as per Bank (Excl GST) | X12: Total Charges Booked in SAP (Excl GST) | Y12: Difference (S-T) | Z12: ROI% (As per LC Advice) | AA12: Penal Interest % | AB12: Interest Calculated (INR) | AC12: Commission Calculated | AD12: Total Charges Calculated | AE12: Excess(Shortfall) (S-Z) | AF12: Interest Remarks | AG12: Management Remarks | AH12: Auditors' Remarks
B13: 2027/01 | C13: Export | D13: HDFC | E13: PAGOUNI SA | F13: 06-APR-2026 | G13: 469BC89260860007 | H13: 5400514061 | I13: 06-APR-2026 | J13: 17-JUL-2026 | K13: =J13-I13 -> 102 | L13: 274518.42 | M13: EUR | N13: 107.36 | O13: =L13*N13 -> 29472298 | P13: 351388.21 | S13: 33972.3 | U13: 6115.02 | V13: 357503.23 | W13: =SUM(P13:R13) -> 351388.21 | X13: =SUMIFS(SAP!H:H,SAP!L:L,Sales!G13,SAP!V:V,Sales!B13) -> 351388.21 | Y13: =ROUND(W13-X13,0) -> 0 | Z13: 4.208 | AA13: 6.208 | AB13: =O13*Z13%*K13/360 -> 351388.38 | AC13: =Q13+R13 -> 0 | AD13: =AB13+AC13 -> 351388.38 | AE13: =ROUND(W13-AD13,0) -> 0 | AF13: OK | AH13: =IF(AF13="Excess","Clarification Required"," ")
B14: 2027/01 | C14: Export | D14: HDFC | E14: KAMARIDAS GLOBAL WIRE ABEE | F14: 02-APR-2026 | G14: 469BC89260890006 | H14: 5400514062 | I14: 02-APR-2026 | J14: 23-JUN-2026 | K14: =J14-I14+1 -> 83 | L14: 155026.8 | M14: EUR | N14: 107.15 | O14: =L14*N14 -> 16611122 | P14: 137791.86 | S14: 21111.12 | U14: 3800 | V14: 141591.86 | W14: =SUM(P14:R14) -> 137791.86 | X14: =SUMIFS(SAP!H:H,SAP!L:L,Sales!G14,SAP!V:V,Sales!B14) -> 137791.86 | Y14: =ROUND(W14-X14,0) -> 0 | Z14: 3.579 | AA14: 5.579 | AB14: =O14*Z14%*K14/360 -> 137068.05 | AC14: =Q14+R14 -> 0 | AD14: =AB14+AC14 -> 137068.05 | AE14: =ROUND(W14-AD14,0) -> 724 | AF14: =IF(AE14>0,"Excess","Shortfall") -> Excess | AH14: =IF(AF14="Excess","Clarification Required"," ") -> Clarification Required
B15: 2027/01 | C15: Export | D15: HDFC | E15: LATTONEDIL S P A MILANO | F15: 13-APR-2026 | G15: 469BC89261030001 | H15: 5400514090 | I15: 13-APR-2026 | J15: 05-JUN-2026 | K15: =J15-I15 -> 53 | L15: 20892.97 | M15: EUR | N15: 108.96 | O15: =L15*N15 -> 2276498 | P15: 12394.2 | Q15: 2000 | R15: 2500 | S15: 6776.5 | U15: 1219.78 | V15: 13613.98 | W15: =SUM(P15:R15) -> 16894.2 | X15: =SUMIFS(SAP!H:H,SAP!L:L,Sales!G15,SAP!V:V,Sales!B15,SAP!P:P, "lc sales") -> 16894.2 | Y15: =ROUND(W15-X15,0) -> 0 | Z15: 3.698 | AA15: 5.698 | AB15: =O15*Z15%*K15/360 -> 12393.888 | AC15: =Q15+R15 -> 4500 | AD15: =AB15+AC15 -> 16893.888 | AE15: =ROUND(W15-AD15,0) -> 0 | AF15: OK | AH15: =IF(AF15="Excess","Clarification Required"," ")
B16: 2027/01 | C16: Export | D16: HDFC | E16: LATTONEDIL S P A MILANO | F16: 13-APR-2026 | G16: 469BC89261030003 | H16: 5400514093 | I16: 13-APR-2026 | J16: 08-JUN-2026 | K16: =J16-I16 -> 56 | L16: 19508.37 | M16: EUR | N16: 108.96 | O16: =L16*N16 -> 2125632 | P16: 12227.49 | Q16: 2000 | R16: 2500 | S16: 6625.63 | U16: 1192.62 | V16: 13420.11 | W16: =SUM(P16:R16) -> 16727.49 | X16: =SUMIFS(SAP!H:H,SAP!L:L,Sales!G16,SAP!V:V,Sales!B16,SAP!P:P, "lc sales") -> 16727.49 | Y16: =ROUND(W16-X16,0) -> 0 | Z16: 3.698 | AA16: 5.698 | AB16: =O16*Z16%*K16/360 -> 12227.58 | AC16: =Q16+R16 -> 4500 | AD16: =AB16+AC16 -> 16727.58 | AE16: =ROUND(W16-AD16,0) -> 0 | AF16: OK | AH16: =IF(AF16="Excess","Clarification Required"," ")
B17: 2027/01 | C17: Export | D17: HDFC | E17: IDROCENTRO SPA | F17: 16-APR-2026 | G17: 469BC89261030011 | H17: 5400514072 | I17: 16-APR-2026 | J17: 18-JUN-2026 | K17: =J17-I17 -> 63 | L17: 224967.27 | M17: EUR | N17: 109.8725 | O17: =L17*N17 -> 24717716 | P17: 161907.02 | Q17: 2000 | R17: 2500 | S17: 29217.72 | U17: 5259.18 | V17: 167166.2 | W17: =SUM(P17:R17) -> 166407.02 | X17: =SUMIFS(SAP!H:H,SAP!L:L,Sales!G17,SAP!V:V,Sales!B17) -> 166407.02 | Y17: =ROUND(W17-X17,0) -> 0 | Z17: 3.743 | AA17: 5.743 | AB17: =O17*Z17%*K17/360 -> 161907.22 | AC17: =Q17+R17 -> 4500 | AD17: =AB17+AC17 -> 166407.22 | AE17: =ROUND(W17-AD17,0) -> 0 | AF17: OK | AH17: =IF(AF17="Excess","Clarification Required"," ")
B18: 2027/01 | C18: Export | D18: HDFC | E18: LATTONEDIL S P A MILANO | F18: 16-APR-2026 | G18: 469BC89261030007 | H18: 5400514083 | I18: 16-APR-2026 | J18: 04-JUN-2026 | K18: =J18-I18 -> 49 | L18: 112383.45 | M18: EUR | N18: 109.8725 | O18: =L18*N18 -> 12347851 | P18: 62907.5 | Q18: 2000 | R18: 2500 | S18: 16847.85 | U18: 3032.62 | V18: 65940.12 | W18: =SUM(P18:R18) -> 67407.5 | X18: =SUMIFS(SAP!H:H,SAP!L:L,Sales!G18,SAP!V:V,Sales!B18) -> 67407.5 | Y18: =ROUND(W18-X18,0) -> 0 | Z18: 3.743 | AA18: 5.743 | AB18: =O18*Z18%*K18/360 -> 62907.84 | AC18: =Q18+R18 -> 4500 | AD18: =AB18+AC18 -> 67407.84 | AE18: =ROUND(W18-AD18,0) -> 0 | AF18: OK | AH18: =IF(AF18="Excess","Clarification Required"," ")
B19: 2027/01 | C19: Export | D19: HDFC | E19: IDROCENTRO SPA | F19: 16-APR-2026 | G19: 469BC89261030010 | H19: 5400154078 | I19: 16-APR-2026 | J19: 22-JUN-2026 | K19: =J19-I19 -> 67 | L19: 82889.55 | M19: EUR | N19: 109.8725 | O19: =L19*N19 -> 9107282.1 | P19: 63442.58 | Q19: 2000 | R19: 2500 | S19: 13607.28 | U19: 2449.32 | V19: 65891.9 | W19: =SUM(P19:R19) -> 67942.58 | X19: =SUMIFS(SAP!H:H,SAP!L:L,Sales!G19,SAP!V:V,Sales!B19) -> 67942.58 | Y19: =ROUND(W19-X19,0) -> 0 | Z19: 3.743 | AA19: 5.743 | AB19: =O19*Z19%*K19/360 -> 63442.592 | AC19: =Q19+R19 -> 4500 | AD19: =AB19+AC19 -> 67942.592 | AE19: =ROUND(W19-AD19,0) -> 0 | AF19: OK | AH19: =IF(AF19="Excess","Clarification Required"," ")
B20: 2027/01 | C20: Export | D20: HDFC | E20: LATTONEDIL ROMANIA SRL | F20: 16-APR-2026 | G20: 469BC89261060001 | H20: 5400514079 | I20: 16-APR-2026 | J20: 01-JUN-2026 | K20: =J20-I20 -> 46 | L20: 211833.14 | M20: EUR | N20: 109.8725 | O20: =L20*N20 -> 23274637 | P20: 111316.22 | Q20: 2000 | R20: 2500 | S20: 27774.64 | U20: 4999.44 | V20: 116315.66 | W20: =SUM(P20:R20) -> 115816.22 | X20: =SUMIFS(SAP!H:H,SAP!L:L,Sales!G20,SAP!V:V,Sales!B20) -> 115816.22 | Y20: =ROUND(W20-X20,0) -> 0 | Z20: 3.743 | AA20: 5.743 | AB20: =O20*Z20%*K20/360 -> 111316.12 | AC20: =Q20+R20 -> 4500 | AD20: =AB20+AC20 -> 115816.12 | AE20: =ROUND(W20-AD20,0) -> 0 | AF20: OK | AH20: =IF(AF20="Excess","Clarification Required"," ")
B21: 2027/01 | C21: Export | D21: HDFC | E21: ISOLPACK S P A | F21: 16-APR-2026 | G21: 469BC89261060002 | H21: 5400514081 | I21: 16-APR-2026 | J21: 03-JUL-2026 | K21: =J21-I21 -> 78 | L21: 78515.47 | M21: EUR | N21: 109.8725 | O21: =L21*N21 -> 8626691 | P21: 69961.31 | Q21: 2000 | R21: 2500 | S21: 13126.69 | U21: 2362.8 | V21: 72324.11 | W21: =SUM(P21:R21) -> 74461.31 | X21: =SUMIFS(SAP!H:H,SAP!L:L,Sales!G21,SAP!V:V,Sales!B21) -> 74461.31 | Y21: =ROUND(W21-X21,0) -> 0 | Z21: 3.743 | AA21: 5.743 | AB21: =O21*Z21%*K21/360 -> 69961.026 | AC21: =Q21+R21 -> 4500 | AD21: =AB21+AC21 -> 74461.026 | AE21: =ROUND(W21-AD21,0) -> 0 | AF21: OK | AH21: =IF(AF21="Excess","Clarification Required"," ")
B22: 2027/01 | C22: Export | D22: HDFC | E22: ISOLPACK SPA SIGLABILE CERIA ISOLPA | F22: 16-APR-2026 | G22: 469BC89261060003 | H22: 5400514086 | I22: 16-APR-2026 | J22: 03-JUL-2026 | K22: =J22-I22 -> 78 | L22: 407974.55 | M22: EUR | N22: 109.8725 | O22: =L22*N22 -> 44825184 | P22: 363525.25 | Q22: 2000 | R22: 2500 | S22: 49325.18 | U22: 8878.54 | V22: 372403.79 | W22: =SUM(P22:R22) -> 368025.25 | X22: =SUMIFS(SAP!H:H,SAP!L:L,Sales!G22,SAP!V:V,Sales!B22) -> 368025.25 | Y22: =ROUND(W22-X22,0) -> 0 | Z22: 3.743 | AA22: 5.743 | AB22: =O22*Z22%*K22/360 -> 363524.77 | AC22: =Q22+R22 -> 4500 | AD22: =AB22+AC22 -> 368024.77 | AE22: =ROUND(W22-AD22,0) -> 0 | AF22: OK | AH22: =IF(AF22="Excess","Clarification Required"," ")
B23: 2027/01 | C23: Export | D23: HDFC | E23: BRAVO INTERNATIONAL RO SRL | F23: 20-APR-2026 | G23: 469BC89261100007 | H23: 5400514068 | I23: 20-APR-2026 | J23: 01-JUL-2026 | K23: =J23-I23 -> 72 | L23: 89033.33 | M23: EUR | N23: 109.5808 | O23: =L23*N23 -> 9756343.5 | P23: 72275.11 | Q23: 4500 | U23: 0 | V23: 72275.11 | W23: =SUM(P23:R23) -> 76775.11 | X23: =SUMIFS(SAP!H:H,SAP!L:L,Sales!G23,SAP!V:V,Sales!B23) -> 76775.11 | Y23: =ROUND(W23-X23,0) -> 0 | Z23: 3.704 | AA23: 5.704 | AB23: =O23*Z23%*K23/360 -> 72274.993 | AC23: =Q23+R23 -> 4500 | AD23: =AB23+AC23 -> 76774.993 | AE23: =ROUND(W23-AD23,0) -> 0 | AF23: OK | AH23: =IF(AF23="Excess","Clarification Required"," ")
B24: 2027/01 | C24: Export | D24: HDFC | E24: TOPANEL PRODUCTION PANELS SA | F24: 20-APR-2026 | G24: 469BC89261100005 | H24: 5400514104 | I24: 20-APR-2026 | J24: 07-JUL-2026 | K24: =J24-I24 -> 78 | L24: 134807.2 | M24: EUR | N24: 109.5808 | O24: =L24*N24 -> 14772281 | P24: 118552.18 | Q24: 4500 | U24: 0 | V24: 118552.18 | W24: =SUM(P24:R24) -> 123052.18 | X24: =SUMIFS(SAP!H:H,SAP!L:L,Sales!G24,SAP!V:V,Sales!B24) -> 123052.18 | Y24: =ROUND(W24-X24,0) -> 0 | Z24: 3.704 | AA24: 5.704 | AB24: =O24*Z24%*K24/360 -> 118552.48 | AC24: =Q24+R24 -> 4500 | AD24: =AB24+AC24 -> 123052.48 | AE24: =ROUND(W24-AD24,0) -> 0 | AF24: OK | AH24: =IF(AF24="Excess","Clarification Required"," ")
B25: 2027/01 | C25: Export | D25: HDFC | E25: TOPANEL PRODUCTION PANELS SA | F25: 20-APR-2026 | G25: 469BC89261100004 | H25: 5400514067 | I25: 20-APR-2026 | J25: 01-JUL-2026 | K25: =J25-I25 -> 72 | L25: 132199.52 | M25: EUR | N25: 109.5808 | O25: =L25*N25 -> 14486529 | P25: 107315.76 | Q25: 4500 | U25: 0 | V25: 107315.76 | W25: =SUM(P25:R25) -> 111815.76 | X25: =SUMIFS(SAP!H:H,SAP!L:L,Sales!G25,SAP!V:V,Sales!B25) -> 111815.76 | Y25: =ROUND(W25-X25,0) -> 0 | Z25: 3.704 | AA25: 5.704 | AB25: =O25*Z25%*K25/360 -> 107316.21 | AC25: =Q25+R25 -> 4500 | AD25: =AB25+AC25 -> 111816.21 | AE25: =ROUND(W25-AD25,0) -> 0 | AF25: OK | AH25: =IF(AF25="Excess","Clarification Required"," ")
B26: 2027/01 | C26: Export | D26: HDFC | E26: LATTONEDIL ROMANIA SRL | F26: 20-APR-2026 | G26: 469BC89261100002 | H26: 5400514065 | I26: 20-APR-2026 | J26: 01-JUN-2026 | K26: =J26-I26 -> 42 | L26: 120378.52 | M26: EUR | N26: 109.5808 | O26: =L26*N26 -> 13191175 | P26: 57003.93 | Q26: 4500 | U26: 0 | V26: 57003.93 | W26: =SUM(P26:R26) -> 61503.93 | X26: =SUMIFS(SAP!H:H,SAP!L:L,Sales!G26,SAP!V:V,Sales!B26) -> 61503.93 | Y26: =ROUND(W26-X26,0) -> 0 | Z26: 3.704 | AA26: 5.704 | AB26: =O26*Z26%*K26/360 -> 57003.462 | AC26: =Q26+R26 -> 4500 | AD26: =AB26+AC26 -> 61503.462 | AE26: =ROUND(W26-AD26,0) -> 0 | AF26: OK | AH26: =IF(AF26="Excess","Clarification Required"," ")
B27: 2027/01 | C27: Export | D27: HDFC | E27: BRAVO INTERNATIONAL RO SRL | F27: 21-APR-2026 | G27: 469BC89261110006 | H27: 5400514098 | I27: 21-APR-2026 | J27: 07-JUL-2026 | K27: =J27-I27 -> 77 | L27: 63932.31 | M27: EUR | N27: 109.5395 | O27: =L27*N27 -> 7003113.3 | P27: 55481.76 | Q27: 2000 | R27: 2500 | U27: 810 | V27: 55481.76 | W27: =SUM(P27:R27) -> 59981.76 | X27: =SUMIFS(SAP!H:H,SAP!L:L,Sales!G27,SAP!V:V,Sales!B27) -> 59981.76 | Y27: =ROUND(W27-X27,0) -> 0 | Z27: 3.704 | AA27: 5.704 | AB27: =O27*Z27%*K27/360 -> 55481.776 | AC27: =Q27+R27 -> 4500 | AD27: =AB27+AC27 -> 59981.776 | AE27: =ROUND(W27-AD27,0) -> 0 | AF27: OK | AH27: =IF(AF27="Excess","Clarification Required"," ")
B28: 2027/01 | C28: Export | D28: HDFC | E28: TOPANEL PRODUCTION PANELS SA | F28: 21-APR-2026 | G28: 469BC89261110008 | H28: 5400514066 | I28: 21-APR-2026 | J28: 31-JUL-2026 | K28: =J28-I28 -> 101 | L28: 89772.92 | M28: EUR | N28: 109.5395 | O28: =L28*N28 -> 9833680.8 | P28: 114908.03 | Q28: 2000 | R28: 2500 | U28: 810 | V28: 114908.03 | W28: =SUM(P28:R28) -> 119408.03 | X28: =SUMIFS(SAP!H:H,SAP!L:L,Sales!G28,SAP!V:V,Sales!B28) -> 119408.03 | Y28: =ROUND(W28-X28,0) -> 0 | Z28: 4.165 | AA28: 6.165 | AB28: =O28*Z28%*K28/360 -> 114907.93 | AC28: =Q28+R28 -> 4500 | AD28: =AB28+AC28 -> 119407.93 | AE28: =ROUND(W28-AD28,0) -> 0 | AF28: OK | AH28: =IF(AF28="Excess","Clarification Required"," ")
B29: 2027/01 | C29: Export | D29: HDFC | E29: SC TERASTEEL SA | F29: 21-APR-2026 | G29: 469BC89261110009 | H29: 5400514096 | I29: 21-APR-2026 | J29: 07-JUL-2026 | K29: =J29-I29 -> 77 | L29: 36362.07 | M29: EUR | N29: 109.5395 | O29: =L29*N29 -> 3983083 | P29: 31556.14 | Q29: 2000 | R29: 2500 | U29: 810 | V29: 31556.14 | W29: =SUM(P29:R29) -> 36056.14 | X29: =SUMIFS(SAP!H:H,SAP!L:L,Sales!G29,SAP!V:V,Sales!B29) -> 36056.14 | Y29: =ROUND(W29-X29,0) -> 0 | Z29: 3.704 | AA29: 5.704 | AB29: =O29*Z29%*K29/360 -> 31555.754 | AC29: =Q29+R29 -> 4500 | AD29: =AB29+AC29 -> 36055.754 | AE29: =ROUND(W29-AD29,0) -> 0 | AF29: OK | AH29: =IF(AF29="Excess","Clarification Required"," ")
B30: 2027/01 | C30: Export | D30: HDFC | E30: INGROS COPERTURE S R L | F30: 23-APR-2026 | G30: 469BC89261130001 | H30: 5400514092 | I30: 24-APR-2026 | J30: 20-JUL-2026 | K30: =J30-I30 -> 87 | L30: 78392.41 | M30: EUR | N30: 109.98 | O30: =L30*N30 -> 8621597.3 | P30: 76278.83 | Q30: 2000 | R30: 2500 | S30: 13121.6 | U30: 2361.88 | V30: 78640.71 | W30: =SUM(P30:R30) -> 80778.83 | X30: =SUMIFS(SAP!H:H,SAP!L:L,Sales!G30,SAP!V:V,Sales!B30) -> 80778.83 | Y30: =ROUND(W30-X30,0) -> 0 | Z30: 3.661 | AA30: 5.661 | AB30: =O30*Z30%*K30/360 -> 76278.863 | AC30: =Q30+R30 -> 4500 | AD30: =AB30+AC30 -> 80778.863 | AE30: =ROUND(W30-AD30,0) -> 0 | AF30: OK | AH30: =IF(AF30="Excess","Clarification Required"," ")
B31: 2027/01 | C31: Export | D31: HDFC | E31: TOPANEL PRODUCTION PANELS SA | F31: 23-APR-2026 | G31: 469BC89261130003 | H31: 5400514121 | I31: 28-APR-2026 | J31: 16-JUL-2026 | K31: =J31-I31 -> 79 | L31: 198877.3 | M31: EUR | N31: 110.515 | O31: =L31*N31 -> 21978925 | P31: 176672.59 | Q31: 2000 | R31: 2500 | S31: 26478.93 | U31: 4766.2 | V31: 181438.79 | W31: =SUM(P31:R31) -> 181172.59 | X31: =SUMIFS(SAP!H:H,SAP!L:L,Sales!G31,SAP!V:V,Sales!B31) -> 181172.59 | Y31: =ROUND(W31-X31,0) -> 0 | Z31: 3.663 | AA31: 5.663 | AB31: =O31*Z31%*K31/360 -> 176672.09 | AC31: =Q31+R31 -> 4500 | AD31: =AB31+AC31 -> 181172.09 | AE31: =ROUND(W31-AD31,0) -> 0 | AF31: OK | AH31: =IF(AF31="Excess","Clarification Required"," ")
B32: 2027/01 | C32: Export | D32: HDFC | E32: ISOLPACK SPA SIGLABILE CERIA ISOLPA | F32: 24-APR-2026 | G32: 469BC89261140003 | H32: 5400514087 | I32: 24-APR-2026 | J32: 20-JUL-2026 | K32: =J32-I32 -> 87 | L32: 123770.74 | M32: EUR | N32: 109.98 | O32: =L32*N32 -> 13612306 | P32: =117138.6+3296.18 -> 120434.78 | Q32: 2000 | R32: 2500 | S32: 17739.86 | U32: 3193.18 | V32: 120331.78 | W32: =SUM(P32:R32) -> 124934.78 | X32: =SUMIFS(SAP!H:H,SAP!L:L,Sales!G32,SAP!V:V,Sales!B32) -> 124934.78 | Y32: =ROUND(W32-X32,0) -> 0 | Z32: 3.661 | AA32: 5.661 | AB32: =O32*Z32%*K32/360 -> 120433.74 | AC32: =Q32+R32 -> 4500 | AD32: =AB32+AC32 -> 124933.74 | AE32: 0 | AF32: OK | AH32: =IF(AF32="Excess","Clarification Required"," ")
B33: 2027/01 | C33: Export | D33: HDFC | E33: ITALPANNELLI IBERICA SA | F33: 24-APR-2026 | G33: 469BC89261140007 | H33: 5400514113 | I33: 24-APR-2026 | J33: 17-JUL-2026 | K33: =J33-I33 -> 84 | L33: 595198.71 | M33: EUR | N33: 109.98 | O33: =L33*N33 -> 65459954 | P33: 559181.21 | Q33: 2000 | R33: 2500 | S33: 60000 | U33: 10800 | V33: 569981.21 | W33: =SUM(P33:R33) -> 563681.21 | X33: =SUMIFS(SAP!H:H,SAP!L:L,Sales!G33,SAP!V:V,Sales!B33) -> 563681.21 | Y33: =ROUND(W33-X33,0) -> 0 | Z33: 3.661 | AA33: 5.661 | AB33: =O33*Z33%*K33/360 -> 559180.75 | AC33: =Q33+R33 -> 4500 | AD33: =AB33+AC33 -> 563680.75 | AE33: =ROUND(W33-AD33,0) -> 0 | AF33: OK | AH33: =IF(AF33="Excess","Clarification Required"," ")
B34: 2027/01 | C34: Export | D34: HDFC | E34: KAMARIDIS GLOBAL WIRE ABEE | F34: 24-APR-2026 | G34: 469BC89261140008 | H34: 5400514094 | I34: 24-APR-2026 | J34: 20-JUL-2026 | K34: =J34-I34 -> 87 | L34: 121261.37 | M34: EUR | N34: 109.98 | O34: =L34*N34 -> 13336325 | P34: 117992.04 | Q34: 2000 | R34: 2500 | S34: 17836.33 | U34: 3210.54 | V34: 121202.58 | W34: =SUM(P34:R34) -> 122492.04 | X34: =SUMIFS(SAP!H:H,SAP!L:L,Sales!G34,SAP!V:V,Sales!B34) -> 122492.04 | Y34: =ROUND(W34-X34,0) -> 0 | Z34: 3.661 | AA34: 5.661 | AB34: =O34*Z34%*K34/360 -> 117992.03 | AC34: =Q34+R34 -> 4500 | AD34: =AB34+AC34 -> 122492.03 | AE34: =ROUND(W34-AD34,0) -> 0 | AF34: OK | AH34: =IF(AF34="Excess","Clarification Required"," ")
B35: 2027/01 | C35: Export | D35: HDFC | E35: LATTONEDIL S P A MILANO | F35: 24-APR-2026 | G35: 469BC89261140009 | H35: 5400514116 | I35: 24-APR-2026 | J35: 19-JUN-2026 | K35: =J35-I35 -> 56 | L35: 143980.48 | M35: EUR | N35: 109.98 | O35: =L35*N35 -> 15834973 | P35: 90178.1 | Q35: 2000 | R35: 2500 | S35: 20334.97 | U35: 3660.3 | V35: 93838.4 | W35: =SUM(P35:R35) -> 94678.1 | X35: =SUMIFS(SAP!H:H,SAP!L:L,Sales!G35,SAP!V:V,Sales!B35) -> 94678.1 | Y35: =ROUND(W35-X35,0) -> 0 | Z35: 3.661 | AA35: 5.661 | AB35: =O35*Z35%*K35/360 -> 90178.413 | AC35: =Q35+R35 -> 4500 | AD35: =AB35+AC35 -> 94678.413 | AE35: =ROUND(W35-AD35,0) -> 0 | AF35: OK | AH35: =IF(AF35="Excess","Clarification Required"," ")
B36: 2027/01 | C36: Export | D36: HDFC | E36: KAMARIDIS GLOBAL WIRE ABEE | F36: 27-APR-2026 | G36: 469BC89261170007 | H36: 5400514119 | I36: 28-APR-2026 | J36: 20-JUL-2026 | K36: =J36-I36 -> 83 | L36: 152902.86 | M36: EUR | N36: 110.515 | O36: =L36*N36 -> 16898060 | P36: 142708.02 | Q36: 2000 | R36: 2500 | S36: 21398.06 | U36: 3851.66 | V36: 146559.68 | W36: =SUM(P36:R36) -> 147208.02 | X36: =SUMIFS(SAP!H:H,SAP!L:L,Sales!G36,SAP!V:V,Sales!B36) -> 147208.02 | Y36: =ROUND(W36-X36,0) -> 0 | Z36: 3.663 | AA36: 5.663 | AB36: =O36*Z36%*K36/360 -> 142708.34 | AC36: =Q36+R36 -> 4500 | AD36: =AB36+AC36 -> 147208.34 | AE36: =ROUND(W36-AD36,0) -> 0 | AF36: OK | AH36: =IF(AF36="Excess","Clarification Required"," ")
B37: 2027/01 | C37: Export | D37: HDFC | E37: LATTONEDIL S P A MILANO | F37: 24-APR-2026 | G37: 469BC89261140010 | H37: 5400514118 | I37: 28-APR-2026 | J37: 19-JUN-2026 | K37: =J37-I37 -> 52 | L37: 67278.72 | M37: EUR | N37: 110.515 | O37: =L37*N37 -> 7435307.7 | P37: 39340.02 | Q37: 2000 | R37: 2500 | S37: 11935.31 | U37: 2148.36 | V37: 41488.38 | W37: =SUM(P37:R37) -> 43840.02 | X37: =SUMIFS(SAP!H:H,SAP!L:L,Sales!G37,SAP!V:V,Sales!B37) -> 43840.02 | Y37: =ROUND(W37-X37,0) -> 0 | Z37: 3.663 | AA37: 5.663 | AB37: =O37*Z37%*K37/360 -> 39340.213 | AC37: =Q37+R37 -> 4500 | AD37: =AB37+AC37 -> 43840.213 | AE37: =ROUND(W37-AD37,0) -> 0 | AF37: OK | AH37: =IF(AF37="Excess","Clarification Required"," ")
B38: 2027/01 | C38: Export | D38: HDFC | E38: IDROCENTRO SPA | F38: 28-APR-2026 | G38: 469BC89261180001 | H38: 5400514075 | I38: 28-APR-2026 | J38: 19-JUN-2026 | K38: =J38-I38 -> 52 | L38: 409750.63 | M38: EUR | N38: 110.515 | O38: =L38*N38 -> 45283591 | P38: 239595.41 | Q38: 2000 | R38: 2500 | S38: 49783.59 | U38: 8961.04 | V38: 248556.45 | W38: =SUM(P38:R38) -> 244095.41 | X38: =SUMIFS(SAP!H:H,SAP!L:L,Sales!G38,SAP!V:V,Sales!B38) -> 244095.41 | Y38: =ROUND(W38-X38,0) -> 0 | Z38: 3.663 | AA38: 5.663 | AB38: =O38*Z38%*K38/360 -> 239595.48 | AC38: =Q38+R38 -> 4500 | AD38: =AB38+AC38 -> 244095.48 | AE38: =ROUND(W38-AD38,0) -> 0 | AF38: OK | AH38: =IF(AF38="Excess","Clarification Required"," ")
B39: 2027/01 | C39: Export | D39: HDFC | E39: LATTONEDIL S P A MILANO | F39: 30-APR-2026 | G39: 469BC89261200004 | H39: 5400514115 | I39: 30-APR-2026 | J39: 19-JUN-2026 | K39: =J39-I39 -> 50 | L39: 397529.59 | M39: EUR | N39: 110.91 | O39: =L39*N39 -> 44090007 | P39: 223511.38 | Q39: 2000 | R39: 2500 | S39: 48590.01 | U39: 8746.2 | V39: 232257.58 | W39: =SUM(P39:R39) -> 228011.38 | X39: =SUMIFS(SAP!H:H,SAP!L:L,Sales!G39,SAP!V:V,Sales!B39) -> 228011.38 | Y39: =ROUND(W39-X39,0) -> 0 | Z39: 3.65 | AA39: 5.65 | AB39: =O39*Z39%*K39/360 -> 223511.84 | AC39: =Q39+R39 -> 4500 | AD39: =AB39+AC39 -> 228011.84 | AE39: =ROUND(W39-AD39,0) -> 0 | AF39: OK | AH39: =IF(AF39="Excess","Clarification Required"," ")
B40: 2027/01 | C40: Export | D40: HDFC | E40: LATTONEDIL ROMANIA SRL | F40: 46129 | G40: 469BC89261070001 | H40: 5400514099 | I40: 46129 | J40: 46178 | K40: =J40-I40 -> 49 | L40: 123340.16 | M40: EUR | N40: 109.41 | O40: =L40*N40 -> 13494647 | P40: 68695.26 | Q40: 2000 | R40: 2500 | U40: =P40*0.18+Q40*0.18+R40*0.18 -> 13175.147 | V40: 232257.58 | W40: =SUM(P40:R40) -> 73195.26 | X40: =SUMIFS(SAP!H:H,SAP!L:L,Sales!G40,SAP!V:V,Sales!B40,SAP!P:P, "sales") -> 73195.26 | Y40: =ROUND(W40-X40,0) -> 0 | Z40: 3.74 | AA40: 5.74 | AB40: =O40*Z40%*K40/360 -> 68695.25 | AC40: =Q40+R40 -> 4500 | AD40: =AB40+AC40 -> 73195.25 | AE40: =ROUND(W40-AD40,0) -> 0 | AF40: OK | AH40: =IF(AF40="Excess","Clarification Required"," ")
B41: 2027/01 | C41: Export | D41: HDFC | E41: BRAVO INTERNATIONAL RO SRL | F41: 46129 | G41: 469BC89261070002 | H41: 5400514095 | I41: 46129 | J41: 46210 | K41: =J41-I41 -> 81 | L41: 44029.98 | M41: EUR | N41: 109.41 | O41: =L41*N41 -> 4817320.1 | P41: 40537.5 | Q41: 2000 | R41: 2500 | U41: =P41*0.18+Q41*0.18+R41*0.18 -> 8106.75 | V41: 232257.58 | W41: =SUM(P41:R41) -> 45037.5 | X41: =SUMIFS(SAP!H:H,SAP!L:L,Sales!G41,SAP!V:V,Sales!B41) -> 45037.5 | Y41: =ROUND(W41-X41,0) -> 0 | Z41: 3.74 | AA41: 5.74 | AB41: =O41*Z41%*K41/360 -> 40537.749 | AC41: =Q41+R41 -> 4500 | AD41: =AB41+AC41 -> 45037.749 | AE41: =ROUND(W41-AD41,0) -> 0 | AF41: OK
...

Sheet Sheet4
A3: Reference No | B3: Sum of Net Amount | C3: Sales | D3: Sales amount | E3: Charges | F3: Amount | G3: Retirement | H3: Amount
A4: 014LCEX253590021 | B4: -1180 | C4: =VLOOKUP(A4,Sales!$G$12:$V$45,1,FALSE) -> #N/A
A5: 014LCEX260910002 | B5: -1770 | C5: =VLOOKUP(A5,Sales!$G$12:$V$45,1,FALSE) -> #N/A
A6: 014LCEX260920001 | B6: -1770 | C6: =VLOOKUP(A6,Sales!$G$12:$V$45,1,FALSE) -> #N/A
A7: 014LCEX260920018 | B7: -1770 | C7: =VLOOKUP(A7,Sales!$G$12:$V$45,1,FALSE) -> #N/A
A8: 014LCEX261010002 | B8: -1770 | C8: =VLOOKUP(A8,Sales!$G$12:$V$45,1,FALSE) -> #N/A
A9: 014LCEX261130002 | B9: -1770 | C9: =VLOOKUP(A9,Sales!$G$12:$V$45,1,FALSE) -> #N/A
A10: 014LCEX261180044 | B10: -1770 | C10: =VLOOKUP(A10,Sales!$G$12:$V$45,1,FALSE) -> #N/A
A11: 469BC04260090001 | B11: -2164595 | C11: =VLOOKUP(A11,Sales!$G$12:$V$45,1,FALSE) -> #N/A
A12: 469BC04260090002 | B12: -3422672 | C12: =VLOOKUP(A12,Sales!$G$12:$V$45,1,FALSE) -> #N/A
A13: 469BC04260150002 | B13: -2409160 | C13: =VLOOKUP(A13,Sales!$G$12:$V$45,1,FALSE) -> #N/A
A14: 469BC04260150003 | B14: -2592392 | C14: =VLOOKUP(A14,Sales!$G$12:$V$45,1,FALSE) -> #N/A
A15: 469BC04260150005 | B15: -2617891 | C15: =VLOOKUP(A15,Sales!$G$12:$V$45,1,FALSE) -> #N/A
... A96: 469LC03261070002 | B96: -13264.38 | C96: =VLOOKUP(A96,Sales!$G$12:$V$45,1,FALSE) -> #N/A
A97: Grand Total | B97: 3.0363347e+08

Sheet Sheet3
A1: Description | B1: Amount | C1: C.D.Falg | D1: Reference No | E1: Value Date | F1: Branch Name | G1: Net Amount | H1: LC Bank Description.1 | I1: Type | J1: Month
A2: CORRESPONDENT BANK CHARGES | B2: 12964.66 | C2: D | D2: 469BC89253450002 | E2: 46026 | F2: BHOWANIPORE | G2: -12964.66 | H2: CORRESPONDENT BANK CHARGES | I2: Sales | J2: 46138 | K2: =VLOOKUP(D2,Sales!$G$3:$G$45,1,FALSE) -> #N/A | M2: =VLOOKUP(D2,Charges!$D$8:$D$25,1,FALSE) -> #N/A | O2: =VLOOKUP(D2,Retirement!$F$12:$F$79,1,FALSE) -> 469BC89253450002 | Q2: 469BC89253450002
A3: CORRESPONDENT BANK CHARGES | B3: 12964.66 | C3: D | D3: 469BC89253430003 | E3: 46026 | F3: BHOWANIPORE | G3: -12964.66 | H3: CORRESPONDENT BANK CHARGES | I3: Sales | J3: 46138 | K3: =VLOOKUP(D3,Sales!$G$3:$G$45,1,FALSE) -> #N/A | M3: =VLOOKUP(D3,Charges!$D$8:$D$25,1,FALSE) -> #N/A | O3: =VLOOKUP(D3,Retirement!$F$12:$F$79,1,FALSE) -> 469BC89253430003 | Q3: 469BC89253430003
A4: CORRESPONDENT BANK CHARGES | B4: 12964.66 | C4: D | D4: 469BC89253390002 | E4: 46026 | F4: BHOWANIPORE | G4: -12964.66 | H4: CORRESPONDENT BANK CHARGES | I4: Sales | J4: 46138 | K4: =VLOOKUP(D4,Sales!$G$3:$G$45,1,FALSE) -> #N/A | M4: =VLOOKUP(D4,Charges!$D$8:$D$25,1,FALSE) -> #N/A | O4: =VLOOKUP(D4,Retirement!$F$12:$F$79,1,FALSE) -> 469BC89253390002 | Q4: 469BC89253390002
A5: CORRESPONDENT BANK CHARGES | B5: 12964.66 | C5: D | D5: 469BC89253390001 | E5: 46026 | F5: BHOWANIPORE | G5: -12964.66 | H5: CORRESPONDENT BANK CHARGES | I5: Sales | J5: 46138 | K5: =VLOOKUP(D5,Sales!$G$3:$G$45,1,FALSE) -> #N/A | M5: =VLOOKUP(D5,Charges!$D$8:$D$25,1,FALSE) -> #N/A | O5: =VLOOKUP(D5,Retirement!$F$12:$F$79,1,FALSE) -> 469BC89253390001 | Q5: 469BC89253390001
A6: CORRESPONDENT BANK CHARGES | B6: 12964.66 | C6: D | D6: 469BC89253430007 | E6: 46026 | F6: BHOWANIPORE | G6: -12964.66 | H6: CORRESPONDENT BANK CHARGES | I6: Sales | J6: 46138 | K6: =VLOOKUP(D6,Sales!$G$3:$G$45,1,FALSE) -> #N/A | M6: =VLOOKUP(D6,Charges!$D$8:$D$25,1,FALSE) -> #N/A | O6: =VLOOKUP(D6,Retirement!$F$12:$F$79,1,FALSE) -> 469BC89253430007 | Q6: 469BC89253430007
A7: CORRESPONDENT BANK CHARGES | B7: 12964.66 | C7: D | D7: 469BC89260350001 | E7: 46026 | F7: BHOWANIPORE | G7: -12964.66 | H7: CORRESPONDENT BANK CHARGES | I7: Sales | J7: 46138 | K7: =VLOOKUP(D7,Sales!$G$3:$G$45,1,FALSE) -> #N/A | M7: =VLOOKUP(D7,Charges!$D$8:$D$25,1,FALSE) -> #N/A | O7: =VLOOKUP(D7,Retirement!$F$12:$F$79,1,FALSE) -> 469BC89260350001 | Q7: 469BC89260350001
A8: CORRESPONDENT BANK CHARGES | B8: 15381.8 | C8: D | D8: 469BC89253460001 | E8: 46026 | F8: BHOWANIPORE | G8: -15381.8 | H8: CORRESPONDENT BANK CHARGES | I8: Sales | J8: 46138 | K8: =VLOOKUP(D8,Sales!$G$3:$G$45,1,FALSE) -> #N/A | M8: =VLOOKUP(D8,Charges!$D$8:$D$25,1,FALSE) -> #N/A | O8: =VLOOKUP(D8,Retirement!$F$12:$F$79,1,FALSE) -> 469BC89253460001 | Q8: 469BC89253460001
A9: GST ON COMMISSION AND CHARGE | B9: 45 | C9: D | D9: 469BC89253450002 | E9: 46057 | F9: BHOWANIPORE | G9: -45 | H9: GST ON COMMISSION AND CHARGE | I9: GST | J9: 46138 | K9: =VLOOKUP(D9,Sales!$G$3:$G$45,1,FALSE) -> #N/A | M9: =VLOOKUP(D9,Charges!$D$8:$D$25,1,FALSE) -> #N/A | O9: =VLOOKUP(D9,Retirement!$F$12:$F$79,1,FALSE) -> 469BC89253450002 | Q9: 469BC89253450002
A10: GST ON COMMISSION AND CHARGE | B10: 45 | C10: D | D10: 469BC89253390002 | E10: 46057 | F10: BHOWANIPORE | G10: -45 | H10: GST ON COMMISSION AND CHARGE | I10: GST | J10: 46138 | K10: =VLOOKUP(D10,Sales!$G$3:$G$45,1,FALSE) -> #N/A | M10: =VLOOKUP(D10,Charges!$D$8:$D$25,1,FALSE) -> #N/A | O10: =VLOOKUP(D10,Retirement!$F$12:$F$79,1,FALSE) -> 469BC89253390002 | Q10: 469BC89253390002
A11: GST ON COMMISSION AND CHARGE | B11: 45 | C11: D | D11: 469BC89253390001 | E11: 46057 | F11: BHOWANIPORE | G11: -45 | H11: GST ON COMMISSION AND CHARGE | I11: GST | J11: 46138 | K11: =VLOOKUP(D11,Sales!$G$3:$G$45,1,FALSE) -> #N/A | M11: =VLOOKUP(D11,Charges!$D$8:$D$25,1,FALSE) -> #N/A | O11: =VLOOKUP(D11,Retirement!$F$12:$F$79,1,FALSE) -> 469BC89253390001 | Q11: 469BC89253390001
A12: LC ADVISING COMMISSION | B12: 1770 | C12: D | D12: 014LCEX260910002 | E12: 46057 | F12: CENTRALPLAZA-KOLKATA | G12: -1770 | H12: LC ADVISING COMMISSION | I12: Issuance | J12: 46138 | K12: =VLOOKUP(D12,Sales!$G$3:$G$45,1,FALSE) -> #N/A | M12: =VLOOKUP(D12,Charges!$D$8:$D$25,1,FALSE) -> 014LCEX260910002 | O12: =VLOOKUP(D12,Retirement!$F$12:$F$79,1,FALSE) -> #N/A | Q12: 014LCEX260910002
A13: LC ADVISING COMMISSION | B13: 1770 | C13: D | D13: 014LCEX260920001 | E13: 46057 | F13: CENTRALPLAZA-KOLKATA | G13: -1770 | H13: LC ADVISING COMMISSION | I13: Issuance | J13: 46138 | K13: =VLOOKUP(D13,Sales!$G$3:$G$45,1,FALSE) -> #N/A | M13: =VLOOKUP(D13,Charges!$D$8:$D$25,1,FALSE) -> 014LCEX260920001 | O13: =VLOOKUP(D13,Retirement!$F$12:$F$79,1,FALSE) -> #N/A | Q13: 014LCEX260920001
... A16: LIQUIDATION OF LOCAL BILL UNDER LC | B16: 3422672 | C16: D | D16: 469BC04260090002 | E16: 46057 | F16: BHOWANIPORE | G16: -3422672 | H16: LIQUIDATION OF LOCAL BILL UNDER LC | I16: Sales | J16: 46138 | K16: =VLOOKUP(D16,Sales!$G$3:$G$45,1,FALSE) -> #N/A | M16: =VLOOKUP(D16,Charges!$D$8:$D$25,1,FALSE) -> #N/A | O16: =VLOOKUP(D16,Retirement!$F$12:$F$79,1,FALSE) -> 469BC04260090002 | Q16: 469BC04260090002
A17: BILLS DISCOUNTED | B17: 16469530 | C17: C | D17: 469BC89260890006 | E17: 46057 | F17: BHOWANIPORE | G17: 16469530 | H17: BILLS DISCOUNTED | I17: Sales | J17: 46138 | K17: =VLOOKUP(D17,Sales!$G$3:$G$45,1,FALSE) -> 469BC89260890006 | L17: =VLOOKUP(D17,Sales!$G$3:$X60,18,FALSE) -> 137791.86 | M17: =VLOOKUP(D17,Charges!$D$8:$D$25,1,FALSE) -> #N/A | O17: =VLOOKUP(D17,Retirement!$F$12:$F$79,1,FALSE) -> #N/A | Q17: 469BC89260890006
A18: GST ON COMMISSION AND CHARGE | B18: 45 | C18: D | D18: 469BC89253430007 | E18: 46057 | F18: BHOWANIPORE | G18: -45 | H18: GST ON COMMISSION AND CHARGE | I18: GST | J18: 46138 | K18: =VLOOKUP(D18,Sales!$G$3:$G$45,1,FALSE) -> #N/A | M18: =VLOOKUP(D18,Charges!$D$8:$D$25,1,FALSE) -> #N/A | O18: =VLOOKUP(D18,Retirement!$F$12:$F$79,1,FALSE) -> 469BC89253430007 | Q18: 469BC89253430007
A19: GST ON COMMISSION AND CHARGE | B19: 45 | C19: D | D19: 469BC89253460001 | E19: 46057 | F19: BHOWANIPORE | G19: -45 | H19: GST ON COMMISSION AND CHARGE | I19: GST | J19: 46138 | K19: =VLOOKUP(D19,Sales!$G$3:$G$45,1,FALSE) -> #N/A | M19: =VLOOKUP(D19,Charges!$D$8:$D$25,1,FALSE) -> #N/A | O19: =VLOOKUP(D19,Retirement!$F$12:$F$79,1,FALSE) -> 469BC89253460001 | Q19: 469BC89253460001
A20: GST ON COMMISSION AND CHARGE | B20: 45 | C20: D | D20: 469BC89260350001 | E20: 46057 | F20: BHOWANIPORE | G20: -45 | H20: GST ON COMMISSION AND CHARGE | I20: GST | J20: 46138 | K20: =VLOOKUP(D20,Sales!$G$3:$G$45,1,FALSE) -> #N/A | M20: =VLOOKUP(D20,Charges!$D$8:$D$25,1,FALSE) -> #N/A | O20: =VLOOKUP(D20,Retirement!$F$12:$F$79,1,FALSE) -> 469BC89260350001 | Q20: 469BC89260350001
A21: LC ADVISING COMMISSION | B21: 1770 | C21: D | D21: 014LCEX260920018 | E21: 46116 | F21: CENTRALPLAZA-KOLKATA | G21: -1770 | H21: LC ADVISING COMMISSION | I21: Issuance | J21: 46138 | K21: =VLOOKUP(D21,Sales!$G$3:$G$45,1,FALSE) -> #N/A | M21: =VLOOKUP(D21,Charges!$D$8:$D$25,1,FALSE) -> 014LCEX260920018 | O21: =VLOOKUP(D21,Retirement!$F$12:$F$79,1,FALSE) -> #N/A | Q21: 014LCEX260920018
A22: COMM ON EXPORT LC AMENDMENT ADVISED | B22: 1180 | C22: D | D22: 014LCEX253590021 | E22: 46116 | F22: CENTRALPLAZA-KOLKATA | G22: -1180 | H22: COMM ON EXPORT LC AMENDMENT ADVISED | I22: Amendment | J22: 46138 | K22: =VLOOKUP(D22,Sales!$G$3:$G$45,1,FALSE) -> #N/A | M22: =VLOOKUP(D22,Charges!$D$8:$D$25,1,FALSE) -> 014LCEX253590021 | O22: =VLOOKUP(D22,Retirement!$F$12:$F$79,1,FALSE) -> #N/A | Q22: 014LCEX253590021
A23: LIQUIDATION OF LOCAL BILL UNDER LC | B23: 2164595 | C23: D | D23: 469BC04260090001 | E23: 46116 | F23: BHOWANIPORE | G23: -2164595 | H23: LIQUIDATION OF LOCAL BILL UNDER LC | I23: Sales | J23: 46138 | K23: =VLOOKUP(D23,Sales!$G$3:$G$45,1,FALSE) -> #N/A | M23: =VLOOKUP(D23,Charges!$D$8:$D$25,1,FALSE) -> #N/A | O23: =VLOOKUP(D23,Retirement!$F$12:$F$79,1,FALSE) -> 469BC04260090001 | Q23: 469BC04260090001
A24: BILLS DISCOUNTED | B24: 29114794 | C24: C | D24: 469BC89260860007 | E24: 46177 | F24: BHOWANIPORE | G24: 29114794 | H24: BILLS DISCOUNTED | I24: Sales | J24: 46138 | K24: =VLOOKUP(D24,Sales!$G$3:$G$45,1,FALSE) -> 469BC89260860007 | L24: =VLOOKUP(D24,Sales!$G$3:$X67,18,FALSE) -> 351388.21 | M24: =VLOOKUP(D24,Charges!$D$8:$D$25,1,FALSE) -> #N/A | O24: =VLOOKUP(D24,Retirement!$F$12:$F$79,1,FALSE) -> #N/A | Q24: 469BC89260860007
A25: COMM ON EXPORT COLL BILL | B25: 2360 | C25: D | D25: 469BC73260940004 | E25: 46177 | F25: BHOWANIPORE | G25: -2360 | H25: COMM ON EXPORT COLL BILL | I25: Sales | J25: 46138 | K25: =VLOOKUP(D25,Sales!$G$3:$G$45,1,FALSE) -> #N/A | M25: =VLOOKUP(D25,Charges!$D$8:$D$25,1,FALSE) -> #N/A | O25: =VLOOKUP(D25,Retirement!$F$12:$F$79,1,FALSE) -> 469BC73260940004 | Q25: 469BC73260940004
A26: LIQUIDATION OF LOCAL BILL UNDER LC | B26: 2409160 | C26: D | D26: 469BC04260150002 | E26: 46177 | F26: BHOWANIPORE | G26: -2409160 | H26: LIQUIDATION OF LOCAL BILL UNDER LC | I26: Sales | J26: 46138 | K26: =VLOOKUP(D26,Sales!$G$3:$G$45,1,FALSE) -> #N/A | M26: =VLOOKUP(D26,Charges!$D$8:$D$25,1,FALSE) -> #N/A | O26: =VLOOKUP(D26,Retirement!$F$12:$F$79,1,FALSE) -> 469BC04260150002 | Q26: 469BC04260150002
A27: INTEREST ON LOCAL BILL DISCOUNTING | B27: 41645.14 | C27: C | D27: 469BC89260090006 | E27: 46207 | F27: BHOWANIPORE | G27: 41645.14 | H27: INTEREST ON LOCAL BILL DISCOUNTING | I27: Sales | J27: 46138 | K27: =VLOOKUP(D27,Sales!$G$3:$G$45,1,FALSE) -> #N/A | M27: =VLOOKUP(D27,Charges!$D$8:$D$25,1,FALSE) -> #N/A | O27: =VLOOKUP(D27,Retirement!$F$12:$F$79,1,FALSE) -> 469BC89260090006 | T27: =G27 -> 41645.14
A28: CORRESPONDENT BANK CHARGES | B28: 7205.9 | C28: D | D28: 469BC89260090006 | E28: 46207 | F28: BHOWANIPORE | G28: -7205.9 | H28: CORRESPONDENT BANK CHARGES | I28: Sales | J28: 46138 | K28: =VLOOKUP(D28,Sales!$G$3:$G$45,1,FALSE) -> #N/A | M28: =VLOOKUP(D28,Charges!$D$8:$D$25,1,FALSE) -> #N/A | O28: =VLOOKUP(D28,Retirement!$F$12:$F$79,1,FALSE) -> 469BC89260090006
A29: CORRESPONDENT BANK CHARGES | B29: 25497.8 | C29: D | D29: 469BC89260500003 | E29: 46207 | F29: BHOWANIPORE | G29: -25497.8 | H29: CORRESPONDENT BANK CHARGES | I29: Sales | J29: 46138 | K29: =VLOOKUP(D29,Sales!$G$3:$G$45,1,FALSE) -> #N/A | M29: =VLOOKUP(D29,Charges!$D$8:$D$25,1,FALSE) -> #N/A | O29: =VLOOKUP(D29,Retirement!$F$12:$F$79,1,FALSE) -> 469BC89260500003 | Q29: 469BC89260500003
A30: COMM ON EXPORT COLL BILL | B30: 2360 | C30: D | D30: 469BC73260970007 | E30: 46207 | F30: BHOWANIPORE | G30: -2360 | H30: COMM ON EXPORT COLL BILL | I30: Sales | J30: 46138 | K30: =VLOOKUP(D30,Sales!$G$3:$G$45,1,FALSE) -> #N/A | M30: =VLOOKUP(D30,Charges!$D$8:$D$25,1,FALSE) -> #N/A | O30: =VLOOKUP(D30,Retirement!$F$12:$F$79,1,FALSE) -> 469BC73260970007 | Q30: 469BC73260970007
A31: LIQUIDATION OF LOCAL BILL UNDER LC | B31: 2592392 | C31: D | D31: 469BC04260150003 | E31: 46207 | F31: BHOWANIPORE | G31: -2592392 | H31: LIQUIDATION OF LOCAL BILL UNDER LC | I31: Sales | J31: 46138 | K31: =VLOOKUP(D31,Sales!$G$3:$G$45,1,FALSE) -> #N/A | M31: =VLOOKUP(D31,Charges!$D$8:$D$25,1,FALSE) -> #N/A | O31: =VLOOKUP(D31,Retirement!$F$12:$F$79,1,FALSE) -> 469BC04260150003 | Q31: 469BC04260150003
A32: GST ON COMMISSION AND CHARGE | B32: 45 | C32: D | D32: 469BC89260500003 | E32: 46238 | F32: BHOWANIPORE | G32: -45 | H32: GST ON COMMISSION AND CHARGE | I32: GST | J32: 46138 | K32: =VLOOKUP(D32,Sales!$G$3:$G$45,1,FALSE) -> #N/A | M32: =VLOOKUP(D32,Charges!$D$8:$D$25,1,FALSE) -> #N/A | O32: =VLOOKUP(D32,Retirement!$F$12:$F$79,1,FALSE) -> 469BC89260500003 | Q32: 469BC89260500003
A33: GST ON COMMISSION AND CHARGE | B33: 45 | C33: D | D33: 469BC89260090006 | E33: 46238 | F33: BHOWANIPORE | G33: -45 | H33: GST ON COMMISSION AND CHARGE | I33: GST | J33: 46138 | K33: =VLOOKUP(D33,Sales!$G$3:$G$45,1,FALSE) -> #N/A | M33: =VLOOKUP(D33,Charges!$D$8:$D$25,1,FALSE) -> #N/A | O33: =VLOOKUP(D33,Retirement!$F$12:$F$79,1,FALSE) -> 469BC89260090006
A34: LIQUIDATION OF LOCAL BILL UNDER LC | B34: 7619134 | C34: D | D34: 469BC04260150013 | E34: 46238 | F34: BHOWANIPORE | G34: -7619134 | H34: LIQUIDATION OF LOCAL BILL UNDER LC | I34: Sales | J34: 46138 | K34: =VLOOKUP(D34,Sales!$G$3:$G$45,1,FALSE) -> #N/A | M34: =VLOOKUP(D34,Charges!$D$8:$D$25,1,FALSE) -> #N/A | O34: =VLOOKUP(D34,Retirement!$F$12:$F$79,1,FALSE) -> 469BC04260150013
A35: LIQUIDATION OF LOCAL BILL UNDER LC | B35: 10202035 | C35: D | D35: 469BC04260190010 | E35: 46269 | F35: BHOWANIPORE | G35: -10202035 | H35: LIQUIDATION OF LOCAL BILL UNDER LC | I35: Sales | J35: 46138 | K35: =VLOOKUP(D35,Sales!$G$3:$G$45,1,FALSE) -> #N/A | M35: =VLOOKUP(D35,Charges!$D$8:$D$25,1,FALSE) -> #N/A | O35: =VLOOKUP(D35,Retirement!$F$12:$F$79,1,FALSE) -> 469BC04260190010 | Q35: 469BC04260190010
A36: COMM ON EXPORT COLL BILL | B36: 2360 | C36: D | D36: 469BC63260990003 | E36: 46269 | F36: BHOWANIPORE | G36: -2360 | H36: COMM ON EXPORT COLL BILL | I36: Sales | J36: 46138 | K36: =VLOOKUP(D36,Sales!$G$3:$G$45,1,FALSE) -> #N/A | M36: =VLOOKUP(D36,Charges!$D$8:$D$25,1,FALSE) -> #N/A | O36: =VLOOKUP(D36,Retirement!$F$12:$F$79,1,FALSE) -> 469BC63260990003 | Q36: 469BC63260990003
A37: COMM ON EXPORT COLL BILL | B37: 2360 | C37: D | D37: 469BC73260990003 | E37: 46269 | F37: BHOWANIPORE | G37: -2360 | H37: COMM ON EXPORT COLL BILL | I37: Sales | J37: 46138 | K37: =VLOOKUP(D37,Sales!$G$3:$G$45,1,FALSE) -> #N/A | M37: =VLOOKUP(D37,Charges!$D$8:$D$25,1,FALSE) -> #N/A | O37: =VLOOKUP(D37,Retirement!$F$12:$F$79,1,FALSE) -> 469BC73260990003 | Q37: 469BC73260990003
A38: COMM ON EXPORT COLL BILL | B38: 2360 | C38: D | D38: 469BC63260990002 | E38: 46269 | F38: BHOWANIPORE | G38: -2360 | H38: COMM ON EXPORT COLL BILL | I38: Sales | J38: 46138 | K38: =VLOOKUP(D38,Sales!$G$3:$G$45,1,FALSE) -> #N/A | M38: =VLOOKUP(D38,Charges!$D$8:$D$25,1,FALSE) -> #N/A | O38: =VLOOKUP(D38,Retirement!$F$12:$F$79,1,FALSE) -> 469BC63260990002 | Q38: 469BC63260990002
A39: LIQUIDATION OF LOCAL BILL UNDER LC | B39: 2617891 | C39: D | D39: 469BC04260150005 | E39: 46299 | F39: BHOWANIPORE | G39: -2617891 | H39: LIQUIDATION OF LOCAL BILL UNDER LC | I39: Sales | J39: 46138 | K39: =VLOOKUP(D39,Sales!$G$3:$G$45,1,FALSE) -> #N/A | M39: =VLOOKUP(D39,Charges!$D$8:$D$25,1,FALSE) -> #N/A | O39: =VLOOKUP(D39,Retirement!$F$12:$F$79,1,FALSE) -> 469BC04260150005 | Q39: 469BC04260150005
A40: LIQUIDATION OF LOCAL BILL UNDER LC | B40: 14435766 | C40: D | D40: 469BC04260150007 | E40: 46299 | F40: BHOWANIPORE | G40: -14435766 | H40: LIQUIDATION OF LOCAL BILL UNDER LC | I40: Sales | J40: 46138 | K40: =VLOOKUP(D40,Sales!$G$3:$G$45,1,FALSE) -> #N/A | M40: =VLOOKUP(D40,Charges!$D$8:$D$25,1,FALSE) -> #N/A | O40: =VLOOKUP(D40,Retirement!$F$12:$F$79,1,FALSE) -> 469BC04260150007 | Q40: 469BC04260150007
A41: LIQUIDATION OF LOCAL BILL UNDER LC | B41: 1996972 | C41: D | D41: 469BC04260150009 | E41: 46299 | F41: BHOWANIPORE | G41: -1996972 | H41: LIQUIDATION OF LOCAL BILL UNDER LC | I41: Sales | J41: 46138 | K41: =VLOOKUP(D41,Sales!$G$3:$G$45,1,FALSE) -> #N/A | M41: =VLOOKUP(D41,Charges!$D$8:$D$25,1,FALSE) -> #N/A | O41: =VLOOKUP(D41,Retirement!$F$12:$F$79,1,FALSE) -> 469BC04260150009 | Q41: 469BC04260150009
A42: LIQUIDATION OF LOCAL BILL UNDER LC | B42: 5137822 | C42: D | D42: 469BC04260150011 | E42: 46299 | F42: BHOWANIPORE | G42: -5137822 | H42: LIQUIDATION OF LOCAL BILL UNDER LC | I42: Sales | J42: 46138 | K42: =VLOOKUP(D42,Sales!$G$3:$G$45,1,FALSE) -> #N/A | M42: =VLOOKUP(D42,Charges!$D$8:$D$25,1,FALSE) -> #N/A | O42: =VLOOKUP(D42,Retirement!$F$12:$F$79,1,FALSE) -> 469BC04260150011 | Q42: 469BC04260150011
...

Sheet Charges
F1: LC Charges - Summary - Apr'26 | J1: Amount in INR
F2: Bank | G2: Total LC Value | H2: Total Charges by Bank | I2: Total Charges Calculated | J2: Excess/(Short) (Incl. Penal Charge if any)
F3: HDFC | G3: =SUMIFS(O:O,C:C,F3) -> 13625650 | H3: =SUMIFS(AC:AC,C:C,F3) -> 21241 | I3: =SUMIFS(AJ:AJ,C:C,F3) -> 21241 | J3: =H3-I3 -> 0
F4: Indian | G4: =SUMIFS(O:O,C:C,F4) -> 3073043.9 | H4: =SUMIFS(AC:AC,C:C,F4) -> 564690 | I4: =SUMIFS(AJ:AJ,C:C,F4) -> 465106.19 | J4: =H4-I4 -> 99583.811
F5: UBI | G5: =SUMIFS(O:O,C:C,F5) -> 7575741.3 | H5: =SUMIFS(AC:AC,C:C,F5) -> 656388.49 | I5: =SUMIFS(AJ:AJ,C:C,F5) -> 1298288.1 | J5: =H5-I5 -> -641899.64
F6: TOTAL | G6: =SUM(G3:G5) -> 24274435 | H6: =SUM(H3:H5) -> 1242319.5 | I6: =SUM(I3:I5) -> 1784635.3 | J6: =SUM(J3:J5) -> -542315.83
S7: As per Bank | AF7: As per Auditor
C8: Bank Name | D8: LC No | E8: User Reference No | F8: Beneficiary | G8: Value Date | H8: LC Open Date | I8: LC Expiry Date | J8: LC Amendment Date | K8: Validity | L8: Usance | M8: Total Days | N8: LC Amount | O8: LC Amount inc Tolerance | P8: Currency | Q8: Exchange Rate | R8: LC Amount (INR) | S8: LC Issuance Charge | T8: LC Usance Charges | U8: Commitment Charges | V8: Amendment Charges | W8: LC Advising Commission | X8: SWIFT/SFMS Charges | Y8: GST | Z8: Total Charges | AA8: Opening/Usuance Charge % | AB8: Amendment Charge % | AC8: Total chgs as per Bank(Excl GST) | AD8: Total chgs as per SAP(Excl GST) | AE8: Difference | AF8: Issuance /Amendment chgs Calculated | AG8: Commitment Chgs | AH8: SWIFT /SFMS Charges | AI8: Advising commission charges | AJ8: Total Charges Calculated (Excl GST) | AK8: Excess (Shortfall) | AL8: Management Remarks | AM8: Auditor Remarks
B9: 2027/01 | C9: HDFC | D9: 014LCEX253590021 | E9: I099891 | F9: TOPANEL PRODUCTION PANELS S.A. | G9: 04-APR-2026 | H9: 23-DEC-2025 | I9: 21-APR-2026 | K9: =I9-H9 -> 119 | L9: =IF(P9="INR",90,180) -> 180 | M9: =K9+L9 -> 299 | N9: 1448400 | O9: =N9 -> 1448400 | P9: EUR | R9: =O9*Q9 -> 0 | V9: 1000 | Y9: =V9*0.18 -> 180 | Z9: =SUM(S9:Y9) -> 1180 | AA9: 0.005 | AB9: 0.005 | AC9: =SUM(S9:X9) -> 1000 | AD9: =SUMIFS(SAP!H:H,SAP!L:L,Charges!D9,SAP!V:V,Charges!B9) -> 1000 | AE9: =ROUND(AC9-AD9,0) -> 0 | AF9: =V9 -> 1000 | AJ9: =SUM(AF9:AI9) -> 1000 | AK9: =ROUND(T9+U9+V9-AJ9+W9+X9,0) -> 0
B10: 2027/01 | C10: HDFC | D10: 014LCEX260920018 | E10: 39010380011215 | F10: PERFICHAPA S.A. | G10: 04-APR-2026 | H10: 01-APR-2026 | I10: 21-JUL-2026 | K10: =I10-H10 -> 111 | L10: =IF(P10="INR",90,180) -> 180 | M10: =K10+L10 -> 291 | N10: 259000 | O10: =N10 -> 259000 | P10: EUR | R10: =O10*Q10 -> 0 | U10: 1500 | Y10: =U10*0.18 -> 270 | Z10: =SUM(S10:Y10) -> 1770 | AA10: 0.005 | AB10: 0.005 | AC10: =SUM(S10:X10) -> 1500 | AD10: =SUMIFS(SAP!H:H,SAP!L:L,Charges!D10,SAP!V:V,Charges!B10) -> 1500 | AE10: =ROUND(AC10-AD10,0) -> 0 | AF10: =U10 -> 1500 | AJ10: =SUM(AF10:AI10) -> 1500 | AK10: =ROUND(T10+U10+V10-AJ10+W10+X10,0) -> 0
B11: 2027/01 | C11: HDFC | D11: 014LCEX260910002 | E11: CDI26700237 | F11: FERPAINEL S.A | G11: 02-APR-2026 | H11: 31-MAR-2026 | I11: 21-JUL-2026 | K11: =I11-H11 -> 112 | L11: =IF(P11="INR",90,180) -> 180 | M11: =K11+L11 -> 292 | N11: 599000 | O11: =N11 -> 599000 | P11: EUR | R11: =O11*Q11 -> 0 | U11: 1500 | Y11: =U11*0.18 -> 270 | Z11: =SUM(S11:Y11) -> 1770 | AA11: 0.005 | AB11: 0.005 | AC11: =SUM(S11:X11) -> 1500 | AD11: =SUMIFS(SAP!H:H,SAP!L:L,Charges!D11,SAP!V:V,Charges!B11) -> 1500 | AE11: =ROUND(AC11-AD11,0) -> 0 | AF11: =U11 -> 1500 | AJ11: =SUM(AF11:AI11) -> 1500 | AK11: =ROUND(T11+U11+V11-AJ11+W11+X11,0) -> 0
B12: 2027/01 | C12: HDFC | D12: 014LCEX260920001 | E12: 10905I0194085387 | F12: METECNO ITALIA SRL | G12: 02-APR-2026 | H12: 01-APR-2026 | I12: 21-JUL-2026 | K12: =I12-H12 -> 111 | L12: =IF(P12="INR",90,180) -> 180 | M12: =K12+L12 -> 291 | N12: 69000 | O12: =N12 -> 69000 | P12: EUR | R12: =O12*Q12 -> 0 | W12: 1500 | Y12: =W12*0.18 -> 270 | Z12: =SUM(S12:Y12) -> 1770 | AA12: 0.005 | AB12: 0.005 | AC12: =SUM(S12:X12) -> 1500 | AD12: =SUMIFS(SAP!H:H,SAP!L:L,Charges!D12,SAP!V:V,Charges!B12) -> 1500 | AE12: =ROUND(AC12-AD12,0) -> 0 | AF12: =U12 -> 0 | AI12: 1500 | AJ12: =SUM(AF12:AI12) -> 1500 | AK12: =ROUND(T12+U12+V12-AJ12+W12+X12,0) -> 0
B13: 2027/01 | C13: HDFC | D13: 014LCEX261010002 | E13: 10907I0194415387 | F13: IDROCENTRO S.P.A. | G13: 13-APR-2026 | H13: 10-APR-2026 | I13: 21-JUL-2026 | K13: =I13-H13 -> 102 | L13: =IF(P13="INR",90,180) -> 180 | M13: =K13+L13 -> 282 | N13: 735000 | O13: =N13 -> 735000 | P13: EUR | R13: =O13*Q13 -> 0 | U13: 1500 | Y13: =U13*0.18 -> 270 | Z13: =SUM(S13:Y13) -> 1770 | AA13: 0.005 | AB13: 0.005 | AC13: =SUM(S13:X13) -> 1500 | AD13: =SUMIFS(SAP!H:H,SAP!L:L,Charges!D13,SAP!V:V,Charges!B13) -> 1500 | AE13: =ROUND(AC13-AD13,0) -> 0 | AF13: =U13 -> 1500 | AJ13: =SUM(AF13:AI13) -> 1500 | AK13: =ROUND(T13+U13+V13-AJ13+W13+X13,0) -> 0
B14: 2027/01 | C14: HDFC | D14: 014LCEX261130002 | E14: CI35863100098037 | F14: ITALPANNELLI IBERICA S.A. | G14: 23-APR-2026 | H14: 22-APR-2026 | I14: 10-SEP-2026 | K14: =I14-H14 -> 141 | L14: =IF(P14="INR",90,180) -> 180 | M14: =K14+L14 -> 321 | N14: 1879000 | O14: =N14 -> 1879000 | P14: EUR | R14: =O14*Q14 -> 0 | U14: 1500 | Y14: =U14*0.18 -> 270 | Z14: =SUM(S14:Y14) -> 1770 | AA14: 0.005 | AB14: 0.005 | AC14: =SUM(S14:X14) -> 1500 | AD14: =SUMIFS(SAP!H:H,SAP!L:L,Charges!D14,SAP!V:V,Charges!B14) -> 1500 | AE14: =ROUND(AC14-AD14,0) -> 0 | AF14: =U14 -> 1500 | AJ14: =SUM(AF14:AI14) -> 1500 | AK14: =ROUND(T14+U14+V14-AJ14+W14+X14,0) -> 0
B15: 2027/01 | C15: HDFC | D15: 014LCEX261180044 | E15: 10905I0201745387 | F15: LATTONEDIL SPA MILANO | G15: 29-APR-2026 | H15: 28-APR-2026 | I15: 31-AUG-2026 | K15: =I15-H15 -> 125 | L15: =IF(P15="INR",90,180) -> 180 | M15: =K15+L15 -> 305 | N15: 1991250 | O15: =N15 -> 1991250 | P15: EUR | R15: =O15*Q15 -> 0 | U15: 1500 | Y15: =U15*0.18 -> 270 | Z15: =SUM(S15:Y15) -> 1770 | AA15: 0.005 | AB15: 0.005 | AC15: =SUM(S15:X15) -> 1500 | AD15: =SUMIFS(SAP!H:H,SAP!L:L,Charges!D15,SAP!V:V,Charges!B15) -> 1500 | AE15: =ROUND(AC15-AD15,0) -> 0 | AF15: =U15 -> 1500 | AJ15: =SUM(AF15:AI15) -> 1500 | AK15: =ROUND(T15+U15+V15-AJ15+W15+X15,0) -> 0
C16: HDFC | D16: 469LC03261070002 | F16: JINDAL STEEL ODISHA LIMITED | G16: 46129 | H16: 46129 | I16: 46157 | K16: =I16-H16 -> 28 | L16: =IF(P16="INR",90,180) -> 90 | M16: =K16+L16 -> 118 | N16: 6645000 | O16: 6645000 | P16: INR | R16: 6645000 | S16: 10741 | X16: 500 | Y16: =S16*0.18+X16*0.18 -> 2023.38 | Z16: =SUM(S16:Y16) -> 13264.38 | AA16: 0.005 | AC16: =SUM(S16:X16) -> 11241 | AD16: =SUMIFS(SAP!H:H,SAP!L:L,Charges!D16,SAP!V:V,"2027/01") -> 11241 | AE16: =ROUND(AC16-AD16,0) -> 0 | AF16: =S16 -> 10741 | AH16: =X16 -> 500 | AJ16: =SUM(AF16:AI16) -> 11241 | AK16: =ROUND(T16+U16+V16-AJ16+W16+X16+S16,0) -> 0
B17: 2027/01 | C17: INDIAN | D17: 0571026FBU000228 | F17: BAOSTEEL SINGAPORE PTE LTD | G17: 46133 | K17: =I17-H17 -> 0 | L17: =IF(P17="INR",90,180) -> 180 | M17: =K17+L17 -> 180 | N17: 600899.22 | O17: =N17 -> 600899.22 | P17: USD | R17: =O17*Q17 -> 0 | X17: 550 | Y17: 99 | Z17: =SUM(S17:Y17) -> 649 | AA17: 0.005 | AC17: =SUM(S17:X17) -> 550 | AD17: =SUMIFS(SAP!H:H,SAP!L:L,Charges!D17,SAP!V:V,Charges!B17) -> 550 | AE17: =ROUND(AC17-AD17,0) -> 0 | AF17: 0 | AH17: =X17 -> 550 | AJ17: =SUM(AF17:AI17) -> 550 | AK17: =ROUND(T17+U17+V17-AJ17+W17+X17,0) -> 0
B18: 2027/01 | C18: INDIAN | D18: 0571026FBU000229 | F18: HONORS COMMODITY HONG KONG COMPANY | G18: 46133 | K18: =I18-H18 -> 0 | L18: =IF(P18="INR",90,180) -> 180 | M18: =K18+L18 -> 180 | N18: 305150.74 | O18: =N18 -> 305150.74 | P18: USD | R18: =O18*Q18 -> 0 | X18: 550 | Y18: 99 | Z18: =SUM(S18:Y18) -> 649 | AA18: 0.005 | AC18: =SUM(S18:X18) -> 550 | AD18: =SUMIFS(SAP!H:H,SAP!L:L,Charges!D18,SAP!V:V,Charges!B18) -> 550 | AE18: =ROUND(AC18-AD18,0) -> 0 | AF18: 0 | AH18: =X18 -> 550 | AJ18: =SUM(AF18:AI18) -> 550 | AK18: =ROUND(T18+U18+V18-AJ18+W18+X18,0) -> 0
B19: 2027/01 | C19: INDIAN | D19: 0571026FBU000230 | F19: HONORS COMMODITY HONG KONG COMPANY | G19: 46142 | K19: =I19-H19 -> 0 | L19: =IF(P19="INR",90,180) -> 180 | M19: =K19+L19 -> 180 | N19: 342714.41 | O19: =N19 -> 342714.41 | P19: USD | R19: =O19*Q19 -> 0 | X19: 550 | Y19: 99 | Z19: =SUM(S19:Y19) -> 649 | AA19: 0.005 | AC19: =SUM(S19:X19) -> 550 | AD19: =SUMIFS(SAP!H:H,SAP!L:L,Charges!D19,SAP!V:V,Charges!B19) -> 550 | AE19: =ROUND(AC19-AD19,0) -> 0 | AF19: 0 | AH19: =X19 -> 550 | AJ19: =SUM(AF19:AI19) -> 550 | AK19: =ROUND(T19+U19+V19-AJ19+W19+X19,0) -> 0
B20: 2027/01 | C20: INDIAN | D20: 0571026FLU000185 | F20: BAOSTEEL SINGAPORE PTE LTD | G20: 46121 | H20: 46121 | J20: 46128 | L20: =IF(P20="INR",90,180) -> 180 | M20: =K20+L20 -> 180 | N20: 1625000 | O20: 1824279.5 | P20: USD | Q20: 93.58 | R20: =O20*Q20 -> 1.7071608e+08 | T20: 426790 | U20: 99584 | V20: 35566 | X20: =550*2 -> 1100 | Y20: =17925+76822+99 -> 94846 | Z20: =SUM(S20:Y20) -> 657886 | AA20: 0.005 | AB20: 0.001 | AC20: =SUM(S20:X20) -> 563040 | AD20: =SUMIFS(SAP!H:H,SAP!L:L,Charges!D20,SAP!V:V,Charges!B20) -> 563039.82 | AE20: =ROUND(AC20-AD20,0) -> 0 | AF20: =(R20*AA20*M20/360)+V20 -> 462356.19 | AH20: =X20 -> 1100 | AJ20: =SUM(AF20:AI20) -> 463456.19 | AK20: =ROUND(T20+U20+V20-AJ20+W20+X20,0) -> 99584
B21: 2027/01 | C21: UBI | D21: 68840M11F0258226-CLM002 | F21: HONORS COMMODITY HONG KONG COMPANY | G21: 46140 | H21: 46140 | I21: 46294 | K21: =I21-H21 -> 154 | L21: =IF(P21="INR",90,180) -> 180 | M21: =K21+L21 -> 334 | N21: 1756215.9 | O21: =N21 -> 1756215.9 | P21: USD | R21: =O21*Q21 -> 0 | X21: 1000 | Y21: 180 | Z21: =SUM(S21:Y21) -> 1180 | AA21: 0.005 | AC21: =SUM(S21:X21) -> 1000 | AD21: =SUMIFS(SAP!H:H,SAP!M:M,Charges!D21,SAP!V:V,Charges!B21) -> 1000 | AE21: =ROUND(AC21-AD21,0) -> 0 | AF21: 0 | AH21: =X21 -> 1000 | AJ21: =SUM(AF21:AI21) -> 1000 | AK21: =ROUND(T21+U21+V21-AJ21+W21+X21,0) -> 0
B22: 2027/01 | C22: UBI | D22: 68840M11F0258226-CLM001 | F22: HONORS COMMODITY HONG KONG COMPANY | G22: 46133 | H22: 46133 | I22: 46294 | K22: =I22-H22 -> 161 | L22: =IF(P22="INR",90,180) -> 180 | M22: =K22+L22 -> 341 | N22: 2316248.2 | O22: =N22 -> 2316248.2 | P22: USD | R22: =O22*Q22 -> 0 | X22: 1000 | Y22: 180 | Z22: =SUM(S22:Y22) -> 1180 | AA22: 0.005 | AC22: =SUM(S22:X22) -> 1000 | AD22: =SUMIFS(SAP!H:H,SAP!M:M,Charges!D22,SAP!V:V,Charges!B22) -> 1000 | AE22: =ROUND(AC22-AD22,0) -> 0 | AF22: 0 | AH22: =X22 -> 1000 | AJ22: =SUM(AF22:AI22) -> 1000 | AK22: =ROUND(T22+U22+V22-AJ22+W22+X22,0) -> 0
B23: 2027/01 | C23: UBI | D23: 68840M11F0351126 | F23: BAOSTEEL SINGAPORE PTE LTD | G23: 46118 | H23: 46118 | I23: 46163 | K23: =I23-H23 -> 45 | L23: =IF(P23="INR",90,180) -> 180 | M23: =K23+L23 -> 225 | N23: 1040000 | O23: 1167759.1 | P23: USD | Q23: 93.25 | R23: =O23*Q23 -> 1.0889353e+08 | T23: 187837.2 | U23: 46959.09 | X23: 2500 | Y23: =33810.7+8452.64+450 -> 42713.34 | Z23: =SUM(S23:Y23) -> 280009.63 | AA23: 0.005 | AB23: 0.001 | AC23: =SUM(S23:X23) -> 237296.29 | AD23: =SUMIFS(SAP!H:H,SAP!M:M,Charges!D23,SAP!V:V,Charges!B23) -> 237296.29 | AE23: =ROUND(AC23-AD23,0) -> 0 | AF23: =K32 -> 331230.7 | AG23: =K36 -> 99365.348 | AH23: =X23 -> 2500 | AJ23: =SUM(AF23:AI23) -> 433096.04 | AK23: =AC23-AJ23 -> -195799.75
B24: 2027/01 | C24: UBI | D24: 68840M11F0351126 - AMD001 | F24: BAOSTEEL SINGAPORE PTE LTD | G24: 46118 | H24: 46118 | I24: 46163 | J24: 46130 | K24: =I24-H24 -> 45 | L24: =IF(P24="INR",90,180) -> 180 | M24: =K24+L24 -> 225 | N24: 1040000 | O24: 1167759.1 | P24: USD | Q24: 93.25 | R24: =O24*Q24 -> 1.0889353e+08 | T24: 242165.89 | U24: 60541.47 | X24: 1000 | Y24: =180+43589.86+10897.46 -> 54667.32 | Z24: =SUM(S24:Y24) -> 358374.68 | AA24: 0.005 | AB24: 0.001 | AC24: =SUM(S24:X24) -> 303707.36 | AD24: =SUMIFS(SAP!H:H,SAP!M:M,Charges!D24,SAP!V:V,Charges!B24) -> 303707.36 | AE24: =ROUND(AC24-AD24,0) -> 0 | AF24: =K32 -> 331230.7 | AG24: =K36 -> 99365.348 | AH24: =X24 -> 1000 | AJ24: =SUM(AF24:AI24) -> 431596.04 | AK24: =AC24-AJ24 -> -127888.68
B25: 2027/01 | C25: UBI | D25: 68840M11F0351126 - AMD002 | F25: BAOSTEEL SINGAPORE PTE LTD | G25: 46118 | H25: 46118 | I25: 46163 | J25: 46136 | K25: =I25-H25 -> 45 | L25: =IF(P25="INR",90,180) -> 180 | M25: =K25+L25 -> 225 | N25: 1040000 | O25: 1167759.1 | P25: USD | Q25: 93.25 | R25: =O25*Q25 -> 1.0889353e+08 | T25: 89907.87 | U25: 22476.97 | X25: 1000 | Y25: =180+4045.85+16183.42 -> 20409.27 | Z25: =SUM(S25:Y25) -> 133794.11 | AA25: 0.005 | AB25: 0.001 | AC25: =SUM(S25:X25) -> 113384.84 | AD25: =SUMIFS(SAP!H:H,SAP!M:M,Charges!D25,SAP!V:V,Charges!B25) -> 113384.83 | AE25: =ROUND(AC25-AD25,0) -> 0 | AF25: =K32 -> 331230.7 | AG25: =K36 -> 99365.348 | AH25: =X25 -> 1000 | AJ25: =SUM(AF25:AI25) -> 431596.04 | AK25: =AC25-AJ25 -> -318211.2
C26: TOTAL | N26: =SUM(N9:N25) -> 23691879 | O26: =SUM(O9:O25) -> 24274435 | R26: =SUM(R9:R25) -> 5.0404167e+08 | S26: =SUM(S9:S25) -> 10741 | T26: =SUM(T9:T25) -> 946700.96 | U26: =SUM(U9:U25) -> 237061.53 | V26: =SUM(V9:V25) -> 36566 | W26: =SUM(W9:W25) -> 1500 | X26: =SUM(X9:X25) -> 9750 | Y26: =SUM(Y9:Y25) -> 217116.31 | Z26: =SUM(Z9:Z25) -> 1459435.8 | AC26: =SUM(AC9:AC25) -> 1242319.5 | AD26: =SUM(AD9:AD25) -> 1242319.3 | AE26: =SUM(AE9:AE25) -> 0 | AF26: =SUM(AF9:AF25) -> 1475289.3 | AG26: =SUM(AG9:AG25) -> 298096.04 | AH26: =SUM(AH9:AH25) -> 9750 | AJ26: =SUM(AJ9:AJ25) -> 1784635.3 | AK26: =SUM(AK9:AK25) -> -542315.64 | AL26: =SUM(AL9:AL25) -> 0 | AM26: =SUM(AM9:AM25) -> 0
H29: Issuance Chgs | I29: 0.0053 | J29: 50000000 | K29: =I29*J29*6/12 -> 132500
I30: 0.0073 | J30: 50000000 | K30: =I30*J30*6/12 -> 182500
I31: 0.00365 | J31: 8893532 | K31: =I31*J31*6/12 -> 16230.696 | M31: 108893532 | N31: 100000000 | O31: =M31-N31 -> 8893532
K32: =SUBTOTAL(9,K29:K31) -> 331230.7
H33: Commitment Chgs | J33: 50000000
I34: 0.00365 | J34: 50000000 | K34: =J34*I34*6/12 -> 91250
I35: 0.001825 | J35: 8893532 | K35: =J35*I35*6/12 -> 8115.348
K36: =SUBTOTAL(9,K34:K35) -> 99365.348

Sheet Retirement
D2: Retirement Charges - Summary - Apr'26 | H2: Amount in INR
D3: Bank Name | E3: BOE Amount | F3: Total Charges by Bank | G3: LC Retirement Charges by Auditor (As per Sanction) | H3: Excess/(Shortfall)
D4: HDFC | E4: =SUMIFS(L:L,D:D,D4) -> 9.2203814e+08 | F4: =SUMIFS(X:X,D:D,D4) -> 2203200.2 | G4: =SUMIFS(AC:AC,D:D,D4) -> 2203200.2 | H4: =F4-G4 -> 0
D5: UBI | E5: =SUMIFS(L:L,D:D,D5) -> 1.3123005e+08 | F5: =SUMIFS(X:X,D:D,D5) -> 2269757.8 | G5: =SUMIFS(AC:AC,D:D,D5) -> 2269757.8 | H5: =F5-G5 -> 0
D6: KOTAK | E6: =SUMIFS(L:L,D:D,D6) -> 68582864 | F6: =SUMIFS(X:X,D:D,D6) -> 8750 | G6: =SUMIFS(AC:AC,D:D,D6) -> 8750 | H6: =F6-G6 -> 0
D7: INDIAN | E7: =SUMIFS(L:L,D:D,D7) -> 1.538478e+08 | F7: =SUMIFS(X:X,D:D,D7) -> 2435541.5 | G7: =SUMIFS(AC:AC,D:D,D7) -> 2435541.5 | H7: =F7-G7 -> 0
D8: UCO | E8: =SUMIFS(L:L,D:D,D8) -> 124000000 | F8: =SUMIFS(X:X,D:D,D8) -> -64667 | G8: =SUMIFS(AC:AC,D:D,D8) -> -64667 | H8: =F8-G8 -> 0
D9: Total | E9: =SUM(E4:E8) -> 1.3996989e+09 | F9: =SUM(F4:F8) -> 6852582.5 | G9: =SUM(G4:G8) -> 6852582.5 | H9: =SUM(H4:H8) -> 0
M11: As per Bank | AA11: As per Auditor
C12: Sales Type | D12: Bank Name | E12: Particulars | F12: Reference Number | G12: Invoice Number | H12: Date | I12: Amount | J12: Currency | K12: Exchange Rate | L12: Amt (INR) | M12: Correspondant Bank Charges | N12: Bill Commission | O12: Bill / Retirement Charges | P12: Interest on bill maturity extension | Q12: Interest Received | R12: Reversal | S12: Penal Interest | T12: Postage/ Courier | U12: Swift Charges | V12: GST | W12: % of Correspondent charges Deduction | X12: Total chgs by Bank (Excl GST) | Y12: Total chgs Booked in SAP (Excl GST) | Z12: Difference (G-N) | AA12: Commission / CBC Charges Calculated | AB12: Retirement Charges Calculated | AC12: Total Charges Calculated (Excl GST) | AD12: Excess/(short) (AE-AF) | AE12: Penal Interest on LC | AF12: Management Remarks | AG12: Auditor Remarks
